Workbook

Sheet Citește-mă
A1: SOUL — model de cost și break-even: fabrică mică vs lanț de producție
A2: ARTEMIS DIGITAL S.R.L. · model construit 15.10.2026, refăcut pe 22.10.2026 pe mărimea de bază S (AMOLED 1,75″ 466×466, 63×70,8×23 mm, LiPo 750 mAh; docs/size-s.json, docs/12-SIZE-S.md §3) · M (prototipul 2.8C) e comparația din Break-even
A4: Întrebarea: „ce ar însemna să facem efectiv o fabrică? mică, pentru asta, sau un lanț de producție măcar”
A6: Scenarii
A7: A — Lanț de producție, totul externalizat: EMS (Felix EMS / EMS-Electra) face PCBA + asamblare + flash + test; CNC + anodizare + sticlă la parteneri; noi facem QC final și ambalare.
A8: B — Atelier T0 propriu: PCBA și carcasa le cumpărăm; asamblarea, flash-ul, calibrarea, testul funcțional, QC, marcarea laser și ambalarea le facem noi.
A9: C — T1: B + celulă CNC proprie (Haas VF-2, sablare, ultrasunete). Anodizarea rămâne externă (Anorom / Alvi / ARSAT).
A10: D — T2: C + linie SMT proprie (NeoDen FP2636 + NeoDen4 + IN6 + AOI).
A11: Volume: 100 / 1.000 / 5.000 / 20.000 unități pe an.
A13: Foi
A14: Rezultate — tabelul-cheie: cost/unitate pe scenariu × volum, capex, costuri fixe, marjă, break-even CNC și SMT, capex pe treaptă.
A15: Ipoteze — TOATE intrările (albastru = editabil, galben = pârghie-cheie), cu sursă + URL + dată sau [estimare] cu raționament.
... A30: • Simplificări: prețul extern între trepte e interpolat logaritmic; la ≥10k carcasa ar trece pe ambutisare 5052 (nemodelat, ar face CNC-ul propriu și mai puțin atractiv).

Sheet Rezultate
A1: REZULTATE: fabrică SOUL vs lanț de producție (mărimea S, EUR fără TVA)
A2: Totul se calculează din foaia Ipoteze. Multe intrări sunt [estimare] până vin ofertele (RFQ): EMS RO, CNC, anodizare, sticlă, PCB custom. Fabrica (B–D) nu schimbă CE/RED, care e per produs (04-COMPLIANCE.md).
B4: 1. Cost total / unitate (fără NRE produs) | C4: =Scenarii!C7 -> 100 | D4: =Scenarii!D7 -> 1000 | E4: =Scenarii!E7 -> 5000 | F4: =Scenarii!F7 -> 20000
A5: A | B5: A — totul externalizat | C5: =Scenarii!C75 -> 224.82959 | D5: =Scenarii!D75 -> 97.46121 | E5: =Scenarii!E75 -> 70.792364 | F5: =Scenarii!F75 -> 57.953274
A6: B | B6: B — atelier T0 (asamblare + test) | C6: =Scenarii!C98 -> 255.89954 | D6: =Scenarii!D98 -> 104.00553 | E6: =Scenarii!E98 -> 73.191865 | F6: =Scenarii!F98 -> 55.172247
A7: C | B7: C — T0 + CNC propriu | C7: =Scenarii!C121 -> 804.88567 | D7: =Scenarii!D121 -> 137.87148 | E7: =Scenarii!E121 -> 71.799896 | F7: =Scenarii!F121 -> 51.095238
A8: D | B8: D — T0 + CNC + SMT propriu | C8: =Scenarii!C144 -> 1123.4202 | D8: =Scenarii!D144 -> 163.38697 | E8: =Scenarii!E144 -> 75.40723 | F8: =Scenarii!F144 -> 51.013738
B9: Cel mai ieftin scenariu | C9: =INDEX($A$5:$A$8,MATCH(MIN(C5:C8),C5:C8,0)) -> A | D9: =INDEX($A$5:$A$8,MATCH(MIN(D5:D8),D5:D8,0)) -> A | E9: =INDEX($A$5:$A$8,MATCH(MIN(E5:E8),E5:E8,0)) -> A | F9: =INDEX($A$5:$A$8,MATCH(MIN(F5:F8),F5:F8,0)) -> D
B11: 2. Cost total / unitate cu NRE produs (PCB, sticlă, matrițe OU pe 3 ani) | C11: =Scenarii!C7 -> 100 | D11: =Scenarii!D7 -> 1000 | E11: =Scenarii!E7 -> 5000 | F11: =Scenarii!F7 -> 20000
A12: A | B12: A — totul externalizat | C12: =Scenarii!C77 -> 253.82959 | D12: =Scenarii!D77 -> 108.55288 | E12: =Scenarii!E77 -> 73.897364 | F12: =Scenarii!F77 -> 58.729524
A13: B | B13: B — atelier T0 (asamblare + test) | C13: =Scenarii!C100 -> 284.89954 | D13: =Scenarii!D100 -> 115.09719 | E13: =Scenarii!E100 -> 76.296865 | F13: =Scenarii!F100 -> 55.948497
A14: C | B14: C — T0 + CNC propriu | C14: =Scenarii!C123 -> 833.88567 | D14: =Scenarii!D123 -> 148.96315 | E14: =Scenarii!E123 -> 74.904896 | F14: =Scenarii!F123 -> 51.871488
A15: D | B15: D — T0 + CNC + SMT propriu | C15: =Scenarii!C146 -> 1152.4202 | D15: =Scenarii!D146 -> 174.47864 | E15: =Scenarii!E146 -> 78.51223 | F15: =Scenarii!F146 -> 51.789988
B16: Cel mai ieftin scenariu | C16: =INDEX($A$12:$A$15,MATCH(MIN(C12:C15),C12:C15,0)) -> A | D16: =INDEX($A$12:$A$15,MATCH(MIN(D12:D15),D12:D15,0)) -> A | E16: =INDEX($A$12:$A$15,MATCH(MIN(E12:E15),E12:E15,0)) -> A | F16: =INDEX($A$12:$A$15,MATCH(MIN(F12:F15),F12:F15,0)) -> D
B18: 3. Cost variabil / unitate | C18: =Scenarii!C7 -> 100 | D18: =Scenarii!D7 -> 1000 | E18: =Scenarii!E7 -> 5000 | F18: =Scenarii!F7 -> 20000
A19: A | B19: A — totul externalizat | C19: =Scenarii!C73 -> 201.71023 | D19: =Scenarii!D73 -> 93.548833 | E19: =Scenarii!E73 -> 70.009888 | F19: =Scenarii!F73 -> 57.65037
A20: B | B20: B — atelier T0 (asamblare + test) | C20: =Scenarii!C96 -> 182.95715 | D20: =Scenarii!D96 -> 81.745755 | E20: =Scenarii!E96 -> 60.606809 | F20: =Scenarii!F96 -> 49.447291
A21: C | B21: C — T0 + CNC propriu | C21: =Scenarii!C119 -> 106.60504 | D21: =Scenarii!D119 -> 58.804795 | E21: =Scenarii!E119 -> 44.938946 | F21: =Scenarii!F119 -> 37.876969
A22: D | B22: D — T0 + CNC + SMT propriu | C22: =Scenarii!C142 -> 106.60504 | D22: =Scenarii!D142 -> 55.015263 | E22: =Scenarii!E142 -> 42.679629 | F22: =Scenarii!F142 -> 36.327629
B24: 4. Capex (investiție inițială) | C24: =Scenarii!C7 -> 100 | D24: =Scenarii!D7 -> 1000 | E24: =Scenarii!E7 -> 5000 | F24: =Scenarii!F7 -> 20000
A25: A | B25: A — totul externalizat | C25: =Scenarii!C59 -> 2135.8073 | D25: =Scenarii!D59 -> 6937.13 | E25: =Scenarii!E59 -> 6937.13 | F25: =Scenarii!F59 -> 13374.26
A26: B | B26: B — atelier T0 (asamblare + test) | C26: =Scenarii!C83 -> 10236.757 | D26: =Scenarii!D83 -> 23361.13 | E26: =Scenarii!E83 -> 26356.13 | F26: =Scenarii!F83 -> 38783.26
A27: C | B27: C — T0 + CNC propriu | C27: =Scenarii!C106 -> 136312.54 | D27: =Scenarii!D106 -> 127555.99 | E27: =Scenarii!E106 -> 130550.99 | F27: =Scenarii!F106 -> 326215.68
A28: D | B28: D — T0 + CNC + SMT propriu | C28: =Scenarii!C129 -> 180441.74 | D28: =Scenarii!D129 -> 164026.41 | E28: =Scenarii!E129 -> 167021.41 | F28: =Scenarii!F129 -> 362686.1
B30: 5. Costuri fixe anuale (chirie, salarii, amortizare, permise/asigurări) | C30: =Scenarii!C7 -> 100 | D30: =Scenarii!D7 -> 1000 | E30: =Scenarii!E7 -> 5000 | F30: =Scenarii!F7 -> 20000
A31: A | B31: A — totul externalizat | C31: =Scenarii!C64 -> 2311.9358 | D31: =Scenarii!D64 -> 3912.3767 | E31: =Scenarii!E64 -> 3912.3767 | F31: =Scenarii!F64 -> 6058.0867
A32: B | B32: B — atelier T0 (asamblare + test) | C32: =Scenarii!C89 -> 7294.239 | D32: =Scenarii!D89 -> 22259.771 | E32: =Scenarii!E89 -> 62925.279 | F32: =Scenarii!F89 -> 114499.13
A33: C | B33: C — T0 + CNC propriu | C33: =Scenarii!C112 -> 69828.062 | D33: =Scenarii!D112 -> 79066.69 | E33: =Scenarii!E112 -> 134304.75 | F33: =Scenarii!F112 -> 264365.39
A34: D | B34: D — T0 + CNC + SMT propriu | C34: =Scenarii!C135 -> 101681.52 | D34: =Scenarii!D135 -> 108371.71 | E34: =Scenarii!E135 -> 163638 | F34: =Scenarii!F135 -> 293722.17
B36: 6. Marjă brută / unitate la prețul de €249 (cu NRE) | C36: =Scenarii!C7 -> 100 | D36: =Scenarii!D7 -> 1000 | E36: =Scenarii!E7 -> 5000 | F36: =Scenarii!F7 -> 20000
A37: A | B37: A — totul externalizat | C37: =Scenarii!C79 -> -4.829587 | D37: =Scenarii!D79 -> 97.232247 | E37: =Scenarii!E79 -> 131.88776 | F37: =Scenarii!F79 -> 147.0556
A38: B | B38: B — atelier T0 (asamblare + test) | C38: =Scenarii!C102 -> -35.899541 | D38: =Scenarii!D102 -> 90.687932 | E38: =Scenarii!E102 -> 129.48826 | F38: =Scenarii!F102 -> 149.83663
A39: C | B39: C — T0 + CNC propriu | C39: =Scenarii!C125 -> -584.88567 | D39: =Scenarii!D125 -> 56.821973 | E39: =Scenarii!E125 -> 130.88023 | F39: =Scenarii!F125 -> 153.91364
A40: D | B40: D — T0 + CNC + SMT propriu | C40: =Scenarii!C148 -> -903.42025 | D40: =Scenarii!D148 -> 31.306484 | E40: =Scenarii!E148 -> 127.27289 | F40: =Scenarii!F148 -> 153.99514
B42: 7. Break-even: de la ce volum producția proprie bate externalizarea | C42: Grilă | D42: Analitic @1.000 | E42: Analitic @5.000 | F42: Analitic @20.000
B43: CNC mărimea S (seturi/an) | C43: ='Break-even'!$C$54 -> 5000 | D43: ='Break-even'!D32 -> 2586.1696 | E43: ='Break-even'!E32 -> 3799.8095 | F43: ='Break-even'!F32 -> 5165.1064
B44: CNC mărimea M, comparație (seturi/an) | C44: ='Break-even'!$C$72 -> 5000 | D44: ='Break-even'!D34 -> 1846.8163 | E44: ='Break-even'!E34 -> 2846.7273 | F44: ='Break-even'!F34 -> 4095.8148
B45: SMT propriu vs EMS România (plăci/an) | C45: ='Break-even'!$C$90 -> 20000 | D45: ='Break-even'!D36 -> 7979.215 | E45: ='Break-even'!E36 -> 13383.462 | F45: ='Break-even'!F36 -> 19516.375
B46: SMT propriu vs JLCPCB (plăci/an) | C46: ='Break-even'!$C$91 -> peste 60.000 | D46: ='Break-even'!D37 -> 47356.231 | E46: ='Break-even'!E37 -> 85519.708 | F46: ='Break-even'!F37 -> 152647.73
B47: Atelier T0 (B) vs box build la EMS (A), unități/an | C47: – | D47: =IF(Scenarii!D73-Scenarii!D96<=0,"niciodată",(Scenarii!D89-Scenarii!D64)/(Scenarii!D73-Scenarii!D96)) -> 1554.4583 | E47: =IF(Scenarii!E73-Scenarii!E96<=0,"niciodată",(Scenarii!E89-Scenarii!E64)/(Scenarii!E73-Scenarii!E96)) -> 6275.9127 | F47: =IF(Scenarii!F73-Scenarii!F96<=0,"niciodată",(Scenarii!F89-Scenarii!F64)/(Scenarii!F73-Scenarii!F96)) -> 13219.554
...

Sheet Ipoteze
A1: IPOTEZE: toate datele de intrare ale modelului (singurul loc unde se modifică cifre)
A2: Legendă: text albastru = intrare editabilă; fond galben = pârghie-cheie; negru = formulă. Coloanele C–F = valori pe volum (100 / 1.000 / 5.000 / 20.000 unit./an); un singur număr în C = valabil pentru toate volumele. Sumele sunt FĂRĂ TVA, cu excepția celor marcate „cu TVA”. Sursele au URL + dată; [estimare] = raționament propriu, de înlocuit cu oferte (RFQ).
A4: Cheie | B4: Parametru | C4: 100 / valoare | D4: 1.000 | E4: 5.000 | F4: 20.000 | G4: Unitate | H4: Sursă / notă (data accesării) | I4: Încredere
A6: 1. Generale
A7: fx_eur_lei | B7: Curs EUR → lei | C7: 5.1 | G7: lei/€ | H7: Vault: „Finanțare — oferte de preț pentru PoC 1.1” (curs folosit pentru estimare, 12.10.2026) | I7: vault
A8: fx_usd_eur | B8: Curs USD → EUR | C8: 0.87 | G8: €/$ | H8: Vault: idem (1 $ ≈ 0,87 €) | I8: vault
A9: vol | B9: Volum analizat | C9: 100 | D9: 1000 | E9: 5000 | F9: 20000 | G9: unit./an | H9: Cererea fondatorului: pilot → sute → mii → zeci de mii pe an | I9: input
A10: price_retail | B10: Preț de vânzare (include TVA dacă firma e plătitoare) | C10: 249 | G10: € | H10: Plan: preț de la €249 (Planul de bani Micul Șmecher) | I10: input
A11: vat_rate | B11: Cotă TVA România | C11: 0.21 | G11: % | H11: Vault BOM.csv P0-17: TVA import 21 % | I11: vault
A12: vat_threshold_lei | B12: Plafon de scutire TVA (cifra de afaceri anuală) | C12: 395000 | G12: lei | H12: [de verificat cu contabilul] 395.000 lei (art. 310 Cod fiscal, din 1.09.2025, după cunoștințele mele; nu am verificat în această rundă). Sub plafon ARTEMIS nu recuperează TVA → TVA = cost real pe achiziții (aplicat automat). | I12: [estimare]
A13: el_route | B13: Arhitectura electronică: 1 = PCB propriu (ESP32-S3-WROOM-1 + panou AMOLED 1,75″), 2 = placă Waveshare ESP32-S3-Touch-AMOLED-1.75 | C13: 2 | D13: 1 | E13: 1 | F13: 1 | G13: cod | H13: 02-MANUFACTURING §11: PCB custom de la ~1k buc. La 100 buc. NRE-ul PCB (~$15–30k) nu se justifică → placa Waveshare [estimare]. Atenție: cu placa Waveshare corpul e S-P0 (25,65 mm, 500 mAh; docs/12 §2.3), nu produsul de 23 mm | I13: [estimare]
A14: pcba_sel | B14: Referință PCBA externalizat: 1 = JLCPCB (Asia), 2 = EMS România | C14: 2 | G14: cod | H14: Lanțul recomandat în cercetare (15.10.2026): Felix EMS / EMS-Electra fac PCBA + box build + flash/test. JLCPCB = cel mai ieftin reper public. | I14: input
A15: days | B15: Zile lucrătoare pe an | C15: 220 | G15: zile | H15: Cercetare T1 (15.10.2026): 220 zile/an | I15: [estimare]
A16: shift_h | B16: Ore pe schimb | C16: 8 | G16: h | H16: Standard | I16: input
A17: oee | B17: Eficiență (timp productiv din schimb) | C17: 0.85 | G17: % | H17: Cercetare T1: ~408 min productive / schimb (85 %) | I17: [estimare]
A18: shift_min | B18: Minute productive pe schimb | C18: =Ipoteze!$C$16*60*Ipoteze!$C$17 -> 408 | G18: min | H18: Formulă | I18: calcul
A19: hours_fte | B19: Ore productive pe an per normă întreagă (FTE) | C19: =Ipoteze!$C$15*Ipoteze!$C$16*Ipoteze!$C$17 -> 1496 | G19: h | H19: Formulă | I19: calcul
A20: max_shifts | B20: Număr maxim de schimburi pe utilaj | C20: 2 | G20: schimburi | H20: Cercetare: T1 se justifică pe 2 schimburi; al 3-lea schimb nemodelat | I20: [estimare]
A21: target_util | B21: Utilizare țintă a stațiilor (rezervă pentru opriri) | C21: 0.8 | G21: % | H21: [estimare] | I21: [estimare]
A22: batches | B22: Loturi de producție pe an | C22: 1 | D22: 4 | E22: 8 | F22: 12 | G22: loturi | H22: [estimare] 1 lot la pilot, apoi trimestrial → lunar | I22: [estimare]
A23: colours | B23: Culori de anodizare active | C23: 2 | D23: 5 | E23: 5 | F23: 5 | G23: culori | H23: 02-MANUFACTURING §3: Founders = argint + grafit; 5 culori ulterior | I23: vault
A24: thr_vol | B24: Volum de la care atelierul are laser, dulap Li-ion și raft de rodaj proprii | C24: 500 | G24: unit./an | H24: [estimare] sub prag: marcare la furnizor/FabLab | I24: [estimare]
A26: 2. BOM per unitate, mărimea S (AMOLED 1,75″ 466×466, 63×70,8×23 mm; docs/size-s.json)
A27: display_usd | B27: Panou rotund AMOLED 1,75" 466×466 CO5300 (QSPI) + touch on-cell | C27: 17 | D27: 10 | E27: 9.5 | F27: 9 | G27: $/buc | H27: docs/12 §1.2: Tailor-Pixels TOH175XRT-02CG $9–17 la eșantion (https://tailorpixels.com/product/1-75-inch-amoled-round-on-cell-touch-466x466-mipi-qspi/, 20.10.2026); docs/12 §3.1 folosește $10 la 1.000; MOQ doar prin RFQ (NoseDisplay, Lianxun) [estimare] | I27: [estimare]
A28: mcu_usd | B28: Modul ESP32-S3-WROOM-1-N16R8 | C28: 4.6 | D28: 3.46 | E28: 3.4 | F28: 3.3 | G28: $/buc | H28: LCSC C2913202: ~$5,16–5,54 @1, ~$3,46 @650+, ~$3,40 @1.300+ (https://www.lcsc.com/product-detail/WiFi-Modules_Espressif-Systems-ESP32-S3-WROOM-1-N16R8_C2913202.html, 15.10.2026); 100 și 20k [estimare] | I28: listare
A29: other_el_usd | B29: Restul componentelor PCB (PMIC, IMU, codec+amp, 2 mic MEMS, USB-C, pogo, ~120 pasive) | C29: 7 | D29: 5 | E29: 4.2 | F29: 3.6 | G29: $/buc | H29: [estimare] nu există încă BOM pentru PCB-ul custom | I29: [estimare]
A30: pcb_bare_usd | B30: PCB gol 4 straturi rotund ~Ø46 mm | C30: 1.6 | D30: 0.8 | E30: 0.56 | F30: 0.44 | G30: $/buc | H30: [estimare] docs/12 §3.1: $0,8 la 1.000 (M: $1,0); reper prototip AISLER 14 € + 0,13 €/cm² (vault) | I30: [estimare]
A31: ws_board_usd | B31: Placă Waveshare ESP32-S3-Touch-AMOLED-1.75 (doar la arhitectura 2; are 2 microfoane, ES7210 + ES8311, difuzor în kit) | C31: 29.99 | G31: $/buc | H31: docs/12 §1.1: $29,99–39,99 pe waveshare.com, verificat 20.10.2026 (https://www.waveshare.com/esp32-s3-touch-amoled-1.75.htm); split pe variante nepublicat | I31: vault
A32: mic_lei | B32: Microfon extern (arhitectura 2) — la S nu trebuie: placa AMOLED-1.75 are 2 microfoane | C32: 0 | G32: lei cu TVA | H32: docs/12 §1.1 [V]; la M era INMP441, Bitmi 20,99 lei | I32: vault
A33: amp_lei | B33: Amplificator extern (arhitectura 2) — la S nu trebuie: codecul ES8311 e pe placă | C33: 0 | G33: lei cu TVA | H33: docs/12 §1.1 [V]; la M era MAX98357A, Robofun 44,18 lei | I33: vault
A34: battery_usd | B34: Celulă LiPo 603040 750 mAh cu PCM (la 100 buc. cu placa Waveshare: 503035 500 mAh, S-P0) | C34: 3.45 | D34: 1.5 | E34: 1.4 | F34: 1.35 | G34: $/buc | H34: docs/12 §3.1: 503035 ≈ 3,00 € la 100 (S-P0); 603040 $1,5 la 1.000 [estimare]; listarea A&S Power 603040 750 mAh (HKTDC). Cere UN38.3 + IEC 62133. | I34: [estimare]
A35: speaker_eur | B35: Difuzor 15×11 mm (la 100 buc.: difuzorul din kitul plăcii Waveshare) | C35: 0 | D35: 0.8 | E35: 0.6 | F35: 0.5 | G35: €/buc | H35: docs/12 §3.1: la 100 fără difuzor separat (kit); volume mari [estimare] | I35: [estimare]
A36: glass_usd | B36: Sticlă frontală plată Ø52, 2.5D, întărită chimic, print negru | C36: 6 | D36: 2.2 | E36: 1.4 | F36: 0.9 | G36: $/buc | H36: docs/12 §3.1: × ~0,75 față de M (Ø74 → Ø52, setup dominant). Felix Glass $2,88–8,11; Hengping $0,60–1,90 @MOQ 100; Saida $0,20–3,00 @MOQ 100 (https://saidaglass.en.made-in-china.com/product/ZdbJyzMDEYWm/, listări 2–2,5 ani) — ales în interval [estimare] | I36: [estimare]
A37: mech_eur | B37: Mecanice mici (șuruburi, magneți, spumă, monedă PCB contacte) | C37: 3.5 | D37: 2 | E37: 1.5 | F37: 1.25 | G37: €/buc | H37: [estimare] docs/12 §3.1 (−0,5 € față de M); BOM.csv @25 ≈ 4,9 € | I37: [estimare]
A38: cable_eur | B38: Cablu USB-C | C38: 2.2 | D38: 1.2 | E38: 0.9 | F38: 0.8 | G38: €/buc | H38: [estimare] BOM.csv P0-15: 2,5 € @25 | I38: [estimare]
A39: chassis_eur | B39: Șasiu + bază/picior din polimer | C39: 4.5 | D39: 2.6 | E39: 1.1 | F39: 0.6 | G39: €/buc | H39: [estimare] docs/12 §3.1: 4,5 € @100, 2,6 € @1.000 (M: 6 / 3,5); BOM.csv P0-10 | I39: [estimare]
A40: ou_eur | B40: Oul OU (carcasă + electronică de încărcare) | C40: 15 | D40: 10 | E40: 6.7 | F40: 5 | G40: €/buc | H40: [estimare] docs/12 §3.1: 15 € @100, 10 € @1.000 (M: 18 / 12); BOM P0-13/14: 33 € @25 (SLA); 02-MANUFACTURING §9: $8–12 la 10k | I40: [estimare]
A41: pack_eur | B41: Ambalaj (cutie rigidă, certificat, ghid, etichetă) | C41: 9 | D41: 5 | E41: 3 | F41: 2.2 | G41: €/buc | H41: [estimare] docs/12 §3.1: 9 € @100, 5 € @1.000 (cutie mai mică); BOM P0-16 8 € + F-03/F-04 2 € @25; Web2Print București de la 25 buc., preț la cerere | I41: [estimare]
A42: freight_pct | B42: Transport din Asia (% din valoarea mărfii) | C42: 0.1 | D42: 0.06 | E42: 0.04 | F42: 0.03 | G42: % | H42: [estimare] BOM P0-17: DHL ~$14/kg; la volum maritim/feroviar | I42: [estimare]
A43: duty_el_pct | B43: Taxă vamală medie componente electronice | C43: 0.02 | G43: % | H43: [estimare] multe componente au 0 % | I43: [estimare]
...

Sheet Scenarii
A1: SCENARII: cost per unitate, capex și costuri fixe (mărimea S, EUR fără TVA; TVA apare ca cost doar sub plafonul de scutire)
A2: A = totul externalizat (EMS face PCBA + box build, CNC + anodizare + sticlă la parteneri; noi QC final + ambalare). B = atelier T0 propriu (asamblare, flash, calibrare, test, QC, ambalare). C = B + celulă CNC proprie. D = C + linie SMT proprie. Anodizarea rămâne externă în toate.
A4: Cheie | B4: Linie | C4: =Ipoteze!C$9 -> 100 | D4: =Ipoteze!D$9 -> 1000 | E4: =Ipoteze!E$9 -> 5000 | F4: =Ipoteze!F$9 -> 20000 | G4: Explicație
A6: Comun tuturor scenariilor
A7: vol | B7: Volum | C7: =Ipoteze!C$9 -> 100 | D7: =Ipoteze!D$9 -> 1000 | E7: =Ipoteze!E$9 -> 5000 | F7: =Ipoteze!F$9 -> 20000
A8: route | B8: Arhitectura electronică (1 = PCB propriu, 2 = placă Waveshare) | C8: =Ipoteze!C$13 -> 2 | D8: =Ipoteze!D$13 -> 1 | E8: =Ipoteze!E$13 -> 1 | F8: =Ipoteze!F$13 -> 1
A9: turnover_lei | B9: Cifră de afaceri estimată | C9: =C7*Ipoteze!$C$10*Ipoteze!$C$7 -> 126990 | D9: =D7*Ipoteze!$C$10*Ipoteze!$C$7 -> 1269900 | E9: =E7*Ipoteze!$C$10*Ipoteze!$C$7 -> 6349500 | F9: =F7*Ipoteze!$C$10*Ipoteze!$C$7 -> 25398000
A10: vatflag | B10: Firma e plătitoare de TVA? (1 = da) | C10: =IF(C9>Ipoteze!$C$12,1,0) -> 0 | D10: =IF(D9>Ipoteze!$C$12,1,0) -> 1 | E10: =IF(E9>Ipoteze!$C$12,1,0) -> 1 | F10: =IF(F9>Ipoteze!$C$12,1,0) -> 1 | G10: peste plafon înregistrarea e obligatorie → TVA deductibil
A11: vatcost | B11: TVA nerecuperabil aplicat achizițiilor | C11: =Ipoteze!$C$11*(1-C10) -> 0.21 | D11: =Ipoteze!$C$11*(1-D10) -> 0 | E11: =Ipoteze!$C$11*(1-E10) -> 0 | F11: =Ipoteze!$C$11*(1-F10) -> 0
A12: hourly_op | B12: Cost operator per oră productivă | C12: =Ipoteze!$C$93*(1+Ipoteze!$C$98)*12/Ipoteze!$C$7/Ipoteze!$C$19 -> 7.2369456 | D12: =Ipoteze!$C$93*(1+Ipoteze!$C$98)*12/Ipoteze!$C$7/Ipoteze!$C$19 -> 7.2369456 | E12: =Ipoteze!$C$93*(1+Ipoteze!$C$98)*12/Ipoteze!$C$7/Ipoteze!$C$19 -> 7.2369456 | F12: =Ipoteze!$C$93*(1+Ipoteze!$C$98)*12/Ipoteze!$C$7/Ipoteze!$C$19 -> 7.2369456
A13: el_comp | B13: Electronică (panou + modul + componente + PCB gol, sau placa Waveshare AMOLED-1.75) | C13: =IF(C8=1,(Ipoteze!C$27+Ipoteze!C$28+Ipoteze!C$29+Ipoteze!C$30)*Ipoteze!$C$8,Ipoteze!$C$31*Ipoteze!$C$8+(Ipoteze!$C$32+Ipoteze!$C$33)/(1+Ipoteze!$C$11)/Ipoteze!$C$7) -> 26.0913 | D13: =IF(D8=1,(Ipoteze!D$27+Ipoteze!D$28+Ipoteze!D$29+Ipoteze!D$30)*Ipoteze!$C$8,Ipoteze!$C$31*Ipoteze!$C$8+(Ipoteze!$C$32+Ipoteze!$C$33)/(1+Ipoteze!$C$11)/Ipoteze!$C$7) -> 16.7562 | E13: =IF(E8=1,(Ipoteze!E$27+Ipoteze!E$28+Ipoteze!E$29+Ipoteze!E$30)*Ipoteze!$C$8,Ipoteze!$C$31*Ipoteze!$C$8+(Ipoteze!$C$32+Ipoteze!$C$33)/(1+Ipoteze!$C$11)/Ipoteze!$C$7) -> 15.3642 | F13: =IF(F8=1,(Ipoteze!F$27+Ipoteze!F$28+Ipoteze!F$29+Ipoteze!F$30)*Ipoteze!$C$8,Ipoteze!$C$31*Ipoteze!$C$8+(Ipoteze!$C$32+Ipoteze!$C$33)/(1+Ipoteze!$C$11)/Ipoteze!$C$7) -> 14.2158
A14: batt | B14: Baterie LiPo 750 mAh (500 mAh la S-P0) | C14: =Ipoteze!C$34*Ipoteze!$C$8 -> 3.0015 | D14: =Ipoteze!D$34*Ipoteze!$C$8 -> 1.305 | E14: =Ipoteze!E$34*Ipoteze!$C$8 -> 1.218 | F14: =Ipoteze!F$34*Ipoteze!$C$8 -> 1.1745
A15: glass | B15: Sticlă frontală 2.5D | C15: =Ipoteze!C$36*Ipoteze!$C$8 -> 5.22 | D15: =Ipoteze!D$36*Ipoteze!$C$8 -> 1.914 | E15: =Ipoteze!E$36*Ipoteze!$C$8 -> 1.218 | F15: =Ipoteze!F$36*Ipoteze!$C$8 -> 0.783
A16: small | B16: Difuzor + mecanice mici + cablu | C16: =Ipoteze!C$35+Ipoteze!C$37+Ipoteze!C$38 -> 5.7 | D16: =Ipoteze!D$35+Ipoteze!D$37+Ipoteze!D$38 -> 4 | E16: =Ipoteze!E$35+Ipoteze!E$37+Ipoteze!E$38 -> 3 | F16: =Ipoteze!F$35+Ipoteze!F$37+Ipoteze!F$38 -> 2.55
A17: imp_el | B17: Subtotal piese importate | C17: =C13+C14+C15+C16 -> 40.0128 | D17: =D13+D14+D15+D16 -> 23.9752 | E17: =E13+E14+E15+E16 -> 20.8002 | F17: =F13+F14+F15+F16 -> 18.7233
A18: log_el | B18: Transport + taxă vamală piese importate | C18: =C17*((1+Ipoteze!C$42)*(1+Ipoteze!$C$43)-1) -> 4.8815616 | D18: =D17*((1+Ipoteze!D$42)*(1+Ipoteze!$C$43)-1) -> 1.9467862 | E18: =E17*((1+Ipoteze!E$42)*(1+Ipoteze!$C$43)-1) -> 1.2646522 | F18: =F17*((1+Ipoteze!F$42)*(1+Ipoteze!$C$43)-1) -> 0.94739898
A19: local | B19: Piese locale (OU, ambalaj, șasiu/bază) | C19: =Ipoteze!C$40+Ipoteze!C$41+Ipoteze!C$39 -> 28.5 | D19: =Ipoteze!D$40+Ipoteze!D$41+Ipoteze!D$39 -> 17.6 | E19: =Ipoteze!E$40+Ipoteze!E$41+Ipoteze!E$39 -> 10.8 | F19: =Ipoteze!F$40+Ipoteze!F$41+Ipoteze!F$39 -> 7.8
A20: bom | B20: BOM total livrat (fără carcasă Al și fără manoperă) | C20: =C17+C18+C19 -> 73.394362 | D20: =D17+D18+D19 -> 43.521986 | E20: =E17+E18+E19 -> 32.864852 | F20: =F17+F18+F19 -> 27.470699
A21: pcba_jlc | B21: PCBA la JLCPCB per placă (manoperă + setup/lot, livrat) | C21: =IF(C8=1,(Ipoteze!$C$51*Ipoteze!C$53+(Ipoteze!$C$47+Ipoteze!$C$48+Ipoteze!$C$49*Ipoteze!$C$50)*Ipoteze!C$22/C7)*Ipoteze!$C$8*(1+Ipoteze!C$42)*(1+Ipoteze!$C$43),0) -> 0 | D21: =IF(D8=1,(Ipoteze!$C$51*Ipoteze!D$53+(Ipoteze!$C$47+Ipoteze!$C$48+Ipoteze!$C$49*Ipoteze!$C$50)*Ipoteze!D$22/D7)*Ipoteze!$C$8*(1+Ipoteze!D$42)*(1+Ipoteze!$C$43),0) -> 0.94075688 | E21: =IF(E8=1,(Ipoteze!$C$51*Ipoteze!E$53+(Ipoteze!$C$47+Ipoteze!$C$48+Ipoteze!$C$49*Ipoteze!$C$50)*Ipoteze!E$22/E7)*Ipoteze!$C$8*(1+Ipoteze!E$42)*(1+Ipoteze!$C$43),0) -> 0.64976308 | F21: =IF(F8=1,(Ipoteze!$C$51*Ipoteze!F$53+(Ipoteze!$C$47+Ipoteze!$C$48+Ipoteze!$C$49*Ipoteze!$C$50)*Ipoteze!F$22/F7)*Ipoteze!$C$8*(1+Ipoteze!F$42)*(1+Ipoteze!$C$43),0) -> 0.4881042
A22: pcba_ems | B22: PCBA la EMS România per placă | C22: =IF(C8=1,Ipoteze!C$54,0) -> 0 | D22: =IF(D8=1,Ipoteze!D$54,0) -> 4 | E22: =IF(E8=1,Ipoteze!E$54,0) -> 2.5 | F22: =IF(F8=1,Ipoteze!F$54,0) -> 1.8
A23: pcba_buy | B23: PCBA externalizat folosit (după selector) | C23: =IF(Ipoteze!$C$14=1,C21,C22) -> 0 | D23: =IF(Ipoteze!$C$14=1,D21,D22) -> 4 | E23: =IF(Ipoteze!$C$14=1,E21,E22) -> 2.5 | F23: =IF(Ipoteze!$C$14=1,F21,F22) -> 1.8
A24: anod_set | B24: Anodizare per set (bază + taxe de lot × culori × loturi / volum) | C24: =Ipoteze!C$57+Ipoteze!$C$58*Ipoteze!$C$8*Ipoteze!C$23*Ipoteze!C$22/C7 -> 4.99 | D24: =Ipoteze!D$57+Ipoteze!$C$58*Ipoteze!$C$8*Ipoteze!D$23*Ipoteze!D$22/D7 -> 4.34 | E24: =Ipoteze!E$57+Ipoteze!$C$58*Ipoteze!$C$8*Ipoteze!E$23*Ipoteze!E$22/E7 -> 2.996 | F24: =Ipoteze!F$57+Ipoteze!$C$58*Ipoteze!$C$8*Ipoteze!F$23*Ipoteze!F$22/F7 -> 2.211
A25: shell_buy | B25: Carcasă S externalizată (CNC + sablare + anodizare, livrată) | C25: =(Ipoteze!C$55+Ipoteze!C$56+C24)*(1+Ipoteze!C$42)*(1+Ipoteze!$C$44) -> 71.46414 | D25: =(Ipoteze!D$55+Ipoteze!D$56+D24)*(1+Ipoteze!D$42)*(1+Ipoteze!$C$44) -> 31.842824 | E25: =(Ipoteze!E$55+Ipoteze!E$56+E24)*(1+Ipoteze!E$42)*(1+Ipoteze!$C$44) -> 23.47671 | F25: =(Ipoteze!F$55+Ipoteze!F$56+F24)*(1+Ipoteze!F$42)*(1+Ipoteze!$C$44) -> 18.73638
A26: mat_eur_kg | B26: Aluminiu net de TVA | C26: =Ipoteze!$C$129/(1+Ipoteze!$C$11)/Ipoteze!$C$7 -> 6.7250041 | D26: =Ipoteze!$C$129/(1+Ipoteze!$C$11)/Ipoteze!$C$7 -> 6.7250041 | E26: =Ipoteze!$C$129/(1+Ipoteze!$C$11)/Ipoteze!$C$7 -> 6.7250041 | F26: =Ipoteze!$C$129/(1+Ipoteze!$C$11)/Ipoteze!$C$7 -> 6.7250041 | G26: €/kg
A27: shell_make_cnc | B27: CNC în casă: material + scule + energie + sablare, cu rebut | C27: =(Ipoteze!$C$127*C26+Ipoteze!$C$130+Ipoteze!$C$131*Ipoteze!$C$125/60*Ipoteze!$C$101/Ipoteze!$C$7+Ipoteze!$C$132)*(1+Ipoteze!$C$133) -> 5.0171488 | D27: =(Ipoteze!$C$127*D26+Ipoteze!$C$130+Ipoteze!$C$131*Ipoteze!$C$125/60*Ipoteze!$C$101/Ipoteze!$C$7+Ipoteze!$C$132)*(1+Ipoteze!$C$133) -> 5.0171488 | E27: =(Ipoteze!$C$127*E26+Ipoteze!$C$130+Ipoteze!$C$131*Ipoteze!$C$125/60*Ipoteze!$C$101/Ipoteze!$C$7+Ipoteze!$C$132)*(1+Ipoteze!$C$133) -> 5.0171488 | F27: =(Ipoteze!$C$127*F26+Ipoteze!$C$130+Ipoteze!$C$131*Ipoteze!$C$125/60*Ipoteze!$C$101/Ipoteze!$C$7+Ipoteze!$C$132)*(1+Ipoteze!$C$133) -> 5.0171488
A28: shell_make | B28: Carcasă S în casă: variabil (CNC propriu + anodizare RO + transport) | C28: =C27+C24+Ipoteze!$C$61 -> 10.507149 | D28: =D27+D24+Ipoteze!$C$61 -> 9.8571488 | E28: =E27+E24+Ipoteze!$C$61 -> 8.5131488 | F28: =F27+F24+Ipoteze!$C$61 -> 7.7281488
A29: board_val | B29: Valoarea componentelor de pe PCB (pentru pierderi SMT) | C29: =IF(C8=1,(Ipoteze!C$28+Ipoteze!C$29+Ipoteze!C$30)*Ipoteze!$C$8,0) -> 0 | D29: =IF(D8=1,(Ipoteze!D$28+Ipoteze!D$29+Ipoteze!D$30)*Ipoteze!$C$8,0) -> 8.0562 | E29: =IF(E8=1,(Ipoteze!E$28+Ipoteze!E$29+Ipoteze!E$30)*Ipoteze!$C$8,0) -> 7.0992 | F29: =IF(F8=1,(Ipoteze!F$28+Ipoteze!F$29+Ipoteze!F$30)*Ipoteze!$C$8,0) -> 6.3858
A30: smt_make | B30: SMT în casă: variabil per placă (consumabile + pierderi suplimentare) | C30: =IF(C8=1,Ipoteze!$C$151+(Ipoteze!$C$152-Ipoteze!$C$153)*C29,0) -> 0 | D30: =IF(D8=1,Ipoteze!$C$151+(Ipoteze!$C$152-Ipoteze!$C$153)*D29,0) -> 0.320843 | E30: =IF(E8=1,Ipoteze!$C$151+(Ipoteze!$C$152-Ipoteze!$C$153)*E29,0) -> 0.306488 | F30: =IF(F8=1,Ipoteze!$C$151+(Ipoteze!$C$152-Ipoteze!$C$153)*F29,0) -> 0.295787
A32: Capacitate și personal (calculat din volum)
A33: asm_h | B33: Ore de manoperă internă T0 pe an | C33: =C7*Ipoteze!C$66/60 -> 75 | D33: =D7*Ipoteze!D$66/60 -> 416.66667 | E33: =E7*Ipoteze!E$66/60 -> 1666.6667 | F33: =F7*Ipoteze!F$66/60 -> 5000
A34: asm_fte_raw | B34: Operatori asamblare necesari (FTE exact) | C34: =C33/Ipoteze!$C$19 -> 0.05013369 | D34: =D33/Ipoteze!$C$19 -> 0.2785205 | E34: =E33/Ipoteze!$C$19 -> 1.114082 | F34: =F33/Ipoteze!$C$19 -> 3.342246
A35: asm_fte | B35: Operatori plătiți (sub 0,5 = part-time/fondator plătit la oră; altfel rotunjit la 0,5) | C35: =IF(C34<0.5,C34,CEILING(C34,0.5)) -> 0.05013369 | D35: =IF(D34<0.5,D34,CEILING(D34,0.5)) -> 0.2785205 | E35: =IF(E34<0.5,E34,CEILING(E34,0.5)) -> 1.5 | F35: =IF(F34<0.5,F34,CEILING(F34,0.5)) -> 3.5
A36: benches | B36: Bancuri ESD | C36: =MAX(1,CEILING(C34,1)) -> 1 | D36: =MAX(1,CEILING(D34,1)) -> 1 | E36: =MAX(1,CEILING(E34,1)) -> 2 | F36: =MAX(1,CEILING(F34,1)) -> 4
A37: jigs | B37: Jig-uri de test | C37: =MAX(1,CEILING(C7*Ipoteze!$C$67/60/Ipoteze!$C$19/Ipoteze!$C$21,1)) -> 1 | D37: =MAX(1,CEILING(D7*Ipoteze!$C$67/60/Ipoteze!$C$19/Ipoteze!$C$21,1)) -> 1 | E37: =MAX(1,CEILING(E7*Ipoteze!$C$67/60/Ipoteze!$C$19/Ipoteze!$C$21,1)) -> 1 | F37: =MAX(1,CEILING(F7*Ipoteze!$C$67/60/Ipoteze!$C$19/Ipoteze!$C$21,1)) -> 2
A38: hc_B | B38: Angajați T0 (număr de persoane) | C38: =CEILING(C35,1)+Ipoteze!C$74+Ipoteze!C$75 -> 1 | D38: =CEILING(D35,1)+Ipoteze!D$74+Ipoteze!D$75 -> 1 | E38: =CEILING(E35,1)+Ipoteze!E$74+Ipoteze!E$75 -> 3 | F38: =CEILING(F35,1)+Ipoteze!F$74+Ipoteze!F$75 -> 6
A39: jig_price | B39: Preț jig de test | C39: =IF(C7<Ipoteze!$C$24,Ipoteze!$C$79,Ipoteze!$C$80)*Ipoteze!$C$8 -> 1565.13 | D39: =IF(D7<Ipoteze!$C$24,Ipoteze!$C$79,Ipoteze!$C$80)*Ipoteze!$C$8 -> 6437.13 | E39: =IF(E7<Ipoteze!$C$24,Ipoteze!$C$79,Ipoteze!$C$80)*Ipoteze!$C$8 -> 6437.13 | F39: =IF(F7<Ipoteze!$C$24,Ipoteze!$C$79,Ipoteze!$C$80)*Ipoteze!$C$8 -> 6437.13
A40: golden | B40: Golden samples (per culoare) | C40: =Ipoteze!C$23*Ipoteze!$C$59 -> 200 | D40: =Ipoteze!D$23*Ipoteze!$C$59 -> 500 | E40: =Ipoteze!E$23*Ipoteze!$C$59 -> 500 | F40: =Ipoteze!F$23*Ipoteze!$C$59 -> 500
A41: cnc_cap | B41: Capacitate CNC: seturi S / mașină / schimb / an | C41: =Ipoteze!$C$18/Ipoteze!$C$125*Ipoteze!$C$15 -> 3740 | D41: =Ipoteze!$C$18/Ipoteze!$C$125*Ipoteze!$C$15 -> 3740 | E41: =Ipoteze!$C$18/Ipoteze!$C$125*Ipoteze!$C$15 -> 3740 | F41: =Ipoteze!$C$18/Ipoteze!$C$125*Ipoteze!$C$15 -> 3740
A42: cnc_m | B42: Mașini CNC necesare | C42: =CEILING(C7/(C41*Ipoteze!$C$20),1) -> 1 | D42: =CEILING(D7/(D41*Ipoteze!$C$20),1) -> 1 | E42: =CEILING(E7/(E41*Ipoteze!$C$20),1) -> 1 | F42: =CEILING(F7/(F41*Ipoteze!$C$20),1) -> 3
A43: cnc_sh | B43: Schimburi CNC | C43: =MIN(Ipoteze!$C$20,CEILING(C7/(C41*C42),1)) -> 1 | D43: =MIN(Ipoteze!$C$20,CEILING(D7/(D41*D42),1)) -> 1 | E43: =MIN(Ipoteze!$C$20,CEILING(E7/(E41*E42),1)) -> 2 | F43: =MIN(Ipoteze!$C$20,CEILING(F7/(F41*F42),1)) -> 2
...

Sheet Break-even
A1: BREAK-EVEN: de la ce volum bate producția proprie externalizarea (CNC și SMT)
A2: Comparație pe proces izolat, cu firma plătitoare de TVA (la aceste volume e obligatoriu). Prețul de cumpărare între volumele din Ipoteze e interpolat logaritmic; peste 20.000 rămâne la valoarea de 20.000. Costul fix propriu crește în trepte (a doua tură, încă o mașină/linie, încă un operator).
A5: 1. Valori pe treptele de volum
A6: tv | B6: Volum (treaptă) | C6: =Ipoteze!C$9 -> 100 | D6: =Ipoteze!D$9 -> 1000 | E6: =Ipoteze!E$9 -> 5000 | F6: =Ipoteze!F$9 -> 20000
A7: S_buy | B7: CNC S: carcasă externalizată livrată (€/set) | C7: =Scenarii!C25 -> 71.46414 | D7: =Scenarii!D25 -> 31.842824 | E7: =Scenarii!E25 -> 23.47671 | F7: =Scenarii!F25 -> 18.73638
A8: S_make | B8: CNC S: carcasă în casă, variabil (€/set) | C8: =Scenarii!C28 -> 10.507149 | D8: =Scenarii!D28 -> 9.8571488 | E8: =Scenarii!E28 -> 8.5131488 | F8: =Scenarii!F28 -> 7.7281488
A9: anod_set | B9: Anodizare per set S | C9: =Scenarii!C24 -> 4.99 | D9: =Scenarii!D24 -> 4.34 | E9: =Scenarii!E24 -> 2.996 | F9: =Scenarii!F24 -> 2.211
A10: Mc_buy | B10: CNC M (comparație): carcasă externalizată livrată (€/set) | C10: =(Ipoteze!C$55*Ipoteze!$C$138+(Ipoteze!C$56+C9)*Ipoteze!$C$139)*(1+Ipoteze!C$42)*(1+Ipoteze!$C$44) -> 110.05478 | D10: =(Ipoteze!D$55*Ipoteze!$C$138+(Ipoteze!D$56+D9)*Ipoteze!$C$139)*(1+Ipoteze!D$42)*(1+Ipoteze!$C$44) -> 49.037949 | E10: =(Ipoteze!E$55*Ipoteze!$C$138+(Ipoteze!E$56+E9)*Ipoteze!$C$139)*(1+Ipoteze!E$42)*(1+Ipoteze!$C$44) -> 36.154134 | F10: =(Ipoteze!F$55*Ipoteze!$C$138+(Ipoteze!F$56+F9)*Ipoteze!$C$139)*(1+Ipoteze!F$42)*(1+Ipoteze!$C$44) -> 28.854025
A11: Mc_make | B11: CNC M (comparație): carcasă în casă, variabil (€/set) | C11: =(Ipoteze!$C$128*Scenarii!C26+Ipoteze!$C$130*Ipoteze!$C$126/Ipoteze!$C$125+Ipoteze!$C$131*Ipoteze!$C$126/60*Ipoteze!$C$101/Ipoteze!$C$7+Ipoteze!$C$132*Ipoteze!$C$139)*(1+Ipoteze!$C$133)+C9*Ipoteze!$C$139+Ipoteze!$C$61 -> 19.251542 | D11: =(Ipoteze!$C$128*Scenarii!D26+Ipoteze!$C$130*Ipoteze!$C$126/Ipoteze!$C$125+Ipoteze!$C$131*Ipoteze!$C$126/60*Ipoteze!$C$101/Ipoteze!$C$7+Ipoteze!$C$132*Ipoteze!$C$139)*(1+Ipoteze!$C$133)+D9*Ipoteze!$C$139+Ipoteze!$C$61 -> 18.250542 | E11: =(Ipoteze!$C$128*Scenarii!E26+Ipoteze!$C$130*Ipoteze!$C$126/Ipoteze!$C$125+Ipoteze!$C$131*Ipoteze!$C$126/60*Ipoteze!$C$101/Ipoteze!$C$7+Ipoteze!$C$132*Ipoteze!$C$139)*(1+Ipoteze!$C$133)+E9*Ipoteze!$C$139+Ipoteze!$C$61 -> 16.180782 | F11: =(Ipoteze!$C$128*Scenarii!F26+Ipoteze!$C$130*Ipoteze!$C$126/Ipoteze!$C$125+Ipoteze!$C$131*Ipoteze!$C$126/60*Ipoteze!$C$101/Ipoteze!$C$7+Ipoteze!$C$132*Ipoteze!$C$139)*(1+Ipoteze!$C$133)+F9*Ipoteze!$C$139+Ipoteze!$C$61 -> 14.971882
A12: ems | B12: SMT: PCBA la EMS România (€/placă) | C12: =Ipoteze!C$54 -> 12 | D12: =Ipoteze!D$54 -> 4 | E12: =Ipoteze!E$54 -> 2.5 | F12: =Ipoteze!F$54 -> 1.8
A13: jlc | B13: SMT: PCBA la JLCPCB livrat (€/placă) | C13: =(Ipoteze!$C$51*Ipoteze!C$53+(Ipoteze!$C$47+Ipoteze!$C$48+Ipoteze!$C$49*Ipoteze!$C$50)*Ipoteze!C$22/C6)*Ipoteze!$C$8*(1+Ipoteze!C$42)*(1+Ipoteze!$C$43) -> 1.5035484 | D13: =(Ipoteze!$C$51*Ipoteze!D$53+(Ipoteze!$C$47+Ipoteze!$C$48+Ipoteze!$C$49*Ipoteze!$C$50)*Ipoteze!D$22/D6)*Ipoteze!$C$8*(1+Ipoteze!D$42)*(1+Ipoteze!$C$43) -> 0.94075688 | E13: =(Ipoteze!$C$51*Ipoteze!E$53+(Ipoteze!$C$47+Ipoteze!$C$48+Ipoteze!$C$49*Ipoteze!$C$50)*Ipoteze!E$22/E6)*Ipoteze!$C$8*(1+Ipoteze!E$42)*(1+Ipoteze!$C$43) -> 0.64976308 | F13: =(Ipoteze!$C$51*Ipoteze!F$53+(Ipoteze!$C$47+Ipoteze!$C$48+Ipoteze!$C$49*Ipoteze!$C$50)*Ipoteze!F$22/F6)*Ipoteze!$C$8*(1+Ipoteze!F$42)*(1+Ipoteze!$C$43) -> 0.4881042
A14: smt_make | B14: SMT: în casă, variabil (€/placă) | C14: =Ipoteze!$C$151+(Ipoteze!$C$152-Ipoteze!$C$153)*(Ipoteze!C$28+Ipoteze!C$29+Ipoteze!C$30)*Ipoteze!$C$8 -> 0.37226 | D14: =Ipoteze!$C$151+(Ipoteze!$C$152-Ipoteze!$C$153)*(Ipoteze!D$28+Ipoteze!D$29+Ipoteze!D$30)*Ipoteze!$C$8 -> 0.320843 | E14: =Ipoteze!$C$151+(Ipoteze!$C$152-Ipoteze!$C$153)*(Ipoteze!E$28+Ipoteze!E$29+Ipoteze!E$30)*Ipoteze!$C$8 -> 0.306488 | F14: =Ipoteze!$C$151+(Ipoteze!$C$152-Ipoteze!$C$153)*(Ipoteze!F$28+Ipoteze!F$29+Ipoteze!F$30)*Ipoteze!$C$8 -> 0.295787
A16: 2. Costuri fixe de bază (o mașină / o linie, un schimb)
A17: mach | B17: Mașină CNC instalată | C17: =Ipoteze!$C$116*Ipoteze!$C$8*(1+Ipoteze!$C$117) -> 74118.78
A18: cnc_common | B18: Echipamente comune CNC | C18: =(Ipoteze!$C$119+Ipoteze!$C$120)/Ipoteze!$C$7+Ipoteze!$C$121+Ipoteze!$C$122 -> 12576.078
A19: emp_over | B19: Cost SSM + medicina muncii + salarizare per angajat suplimentar / an | C19: =(Ipoteze!$C$109*12+Ipoteze!$C$110+Ipoteze!$C$111*12)/Ipoteze!$C$7 -> 189.01961
A20: op_prog | B20: Programator CNC, cost anual | C20: =Ipoteze!$C$95*(1+Ipoteze!$C$98)*12/Ipoteze!$C$7 -> 25983.529
A21: op_cnc | B21: Operator CNC, cost anual | C21: =Ipoteze!$C$96*(1+Ipoteze!$C$98)*12/Ipoteze!$C$7 -> 14435.294
A22: space_cost | B22: Chirie + servicii per m² / an | C22: =(Ipoteze!$C$99+Ipoteze!$C$100)*12 -> 80.4
A23: capS | B23: Capacitate CNC S: seturi / mașină / schimb / an | C23: =Ipoteze!$C$18/Ipoteze!$C$125*Ipoteze!$C$15 -> 3740
A24: capMc | B24: Capacitate CNC M (comparație): seturi / mașină / schimb / an | C24: =Ipoteze!$C$18/Ipoteze!$C$126*Ipoteze!$C$15 -> 1994.6667
A25: smt_line | B25: Capex linie SMT | C25: =Ipoteze!$C$142+Ipoteze!$C$143+(Ipoteze!$C$144+Ipoteze!$C$145)*Ipoteze!$C$8+Ipoteze!$C$146+Ipoteze!$C$147+Ipoteze!$C$148 -> 36470.42
A26: smt_cap | B26: Capacitate SMT: plăci / linie / schimb / an | C26: =Ipoteze!$C$18/(Ipoteze!$C$52/Ipoteze!$C$149*60+Ipoteze!$C$150)*Ipoteze!$C$15 -> 21892.683
A27: tech | B27: Tehnician SMT, cost anual | C27: =Ipoteze!$C$94*(1+Ipoteze!$C$98)*12/Ipoteze!$C$7 -> 15638.235
A28: F_cnc1 | B28: Cost fix anual celulă CNC (1 mașină, 1 schimb, 1 programator) | C28: =(1*('Break-even'!$C$17+Ipoteze!$C$118)+'Break-even'!$C$18)/Ipoteze!$C$90+'Break-even'!$C$20+(1-1)*'Break-even'!$C$21+1*'Break-even'!$C$19+(1*Ipoteze!$C$134+Ipoteze!$C$135)*'Break-even'!$C$22+Ipoteze!$C$124*1*'Break-even'!$C$17+Ipoteze!$C$123*Ipoteze!$C$8+Ipoteze!$C$136 -> 56858.684
A29: F_smt1 | B29: Cost fix anual linie SMT (1 linie, 1 schimb, 1 tehnician) | C29: =1*'Break-even'!$C$25/Ipoteze!$C$90+1*('Break-even'!$C$27+'Break-even'!$C$19)+1*Ipoteze!$C$155*'Break-even'!$C$22+Ipoteze!$C$124*1*'Break-even'!$C$25+Ipoteze!$C$154*Ipoteze!$C$16*Ipoteze!$C$15*1*1*Ipoteze!$C$101/Ipoteze!$C$7+Ipoteze!$C$156 -> 29356.785
A31: 3. Break-even analitic pe trepte (o mașină / o linie, un schimb): N* = cost fix / (preț cumpărare − variabil propriu)
A32: be_S | B32: CNC S: volum de break-even (seturi/an) | C32: =IF(C7-C8<=0,"niciodată",'Break-even'!$C$28/(C7-C8)) -> 932.76723 | D32: =IF(D7-D8<=0,"niciodată",'Break-even'!$C$28/(D7-D8)) -> 2586.1696 | E32: =IF(E7-E8<=0,"niciodată",'Break-even'!$C$28/(E7-E8)) -> 3799.8095 | F32: =IF(F7-F8<=0,"niciodată",'Break-even'!$C$28/(F7-F8)) -> 5165.1064
A33: be_S_ok | B33: … încape într-o mașină pe un schimb? (1 = da) | C33: =IF(ISNUMBER(C32),IF(C32<='Break-even'!$C$23,1,0),0) -> 1 | D33: =IF(ISNUMBER(D32),IF(D32<='Break-even'!$C$23,1,0),0) -> 1 | E33: =IF(ISNUMBER(E32),IF(E32<='Break-even'!$C$23,1,0),0) -> 0 | F33: =IF(ISNUMBER(F32),IF(F32<='Break-even'!$C$23,1,0),0) -> 0
A34: be_Mc | B34: CNC M (comparație): volum de break-even (seturi/an) | C34: =IF(C10-C11<=0,"niciodată",'Break-even'!$C$28/(C10-C11)) -> 626.17467 | D34: =IF(D10-D11<=0,"niciodată",'Break-even'!$C$28/(D10-D11)) -> 1846.8163 | E34: =IF(E10-E11<=0,"niciodată",'Break-even'!$C$28/(E10-E11)) -> 2846.7273 | F34: =IF(F10-F11<=0,"niciodată",'Break-even'!$C$28/(F10-F11)) -> 4095.8148
A35: be_Mc_ok | B35: … încape într-o mașină pe un schimb? (1 = da) | C35: =IF(ISNUMBER(C34),IF(C34<='Break-even'!$C$24,1,0),0) -> 1 | D35: =IF(ISNUMBER(D34),IF(D34<='Break-even'!$C$24,1,0),0) -> 1 | E35: =IF(ISNUMBER(E34),IF(E34<='Break-even'!$C$24,1,0),0) -> 0 | F35: =IF(ISNUMBER(F34),IF(F34<='Break-even'!$C$24,1,0),0) -> 0
A36: be_ems | B36: SMT vs EMS România: volum de break-even (plăci/an) | C36: =IF(C12-C14<=0,"niciodată",'Break-even'!$C$29/(C12-C14)) -> 2524.7198 | D36: =IF(D12-D14<=0,"niciodată",'Break-even'!$C$29/(D12-D14)) -> 7979.215 | E36: =IF(E12-E14<=0,"niciodată",'Break-even'!$C$29/(E12-E14)) -> 13383.462 | F36: =IF(F12-F14<=0,"niciodată",'Break-even'!$C$29/(F12-F14)) -> 19516.375
A37: be_jlc | B37: SMT vs JLCPCB: volum de break-even (plăci/an) | C37: =IF(C13-C14<=0,"niciodată",'Break-even'!$C$29/(C13-C14)) -> 25949.867 | D37: =IF(D13-D14<=0,"niciodată",'Break-even'!$C$29/(D13-D14)) -> 47356.231 | E37: =IF(E13-E14<=0,"niciodată",'Break-even'!$C$29/(E13-E14)) -> 85519.708 | F37: =IF(F13-F14<=0,"niciodată",'Break-even'!$C$29/(F13-F14)) -> 152647.73
A39: 4. Grilă CNC mărimea S (Haas VF-2 nou; anodizare externă în ambele variante)
A40: Volum (seturi/an) | B40: Treaptă | C40: Cumpărat €/set | D40: Cumpărat €/an | E40: Mașini | F40: Schimburi | G40: Operatori | H40: Fix propriu €/an | I40: Variabil propriu €/set | J40: Propriu €/an | K40: Propriu €/set | L40: Economie €/an | M40: Propriu mai ieftin?
A41: 250 | B41: =MATCH(A41,'Break-even'!$C$6:$F$6,1) -> 1 | C41: =IF(B41>=4,INDEX('Break-even'!$C$7:$F$7,1,4),INDEX('Break-even'!$C$7:$F$7,1,B41)+(INDEX('Break-even'!$C$7:$F$7,1,B41+1)-INDEX('Break-even'!$C$7:$F$7,1,B41))*LN(A41/INDEX('Break-even'!$C$6:$F$6,1,B41))/LN(INDEX('Break-even'!$C$6:$F$6,1,B41+1)/INDEX('Break-even'!$C$6:$F$6,1,B41))) -> 55.697233 | D41: =A41*C41 -> 13924.308 | E41: =CEILING(A41/('Break-even'!$C$23*Ipoteze!$C$20),1) -> 1 | F41: =MIN(Ipoteze!$C$20,CEILING(A41/('Break-even'!$C$23*E41),1)) -> 1 | G41: =F41*CEILING(E41/Ipoteze!$C$137,1) -> 1 | H41: =(E41*('Break-even'!$C$17+Ipoteze!$C$118)+'Break-even'!$C$18)/Ipoteze!$C$90+'Break-even'!$C$20+(G41-1)*'Break-even'!$C$21+G41*'Break-even'!$C$19+(E41*Ipoteze!$C$134+Ipoteze!$C$135)*'Break-even'!$C$22+Ipoteze!$C$124*E41*'Break-even'!$C$17+Ipoteze!$C$123*Ipoteze!$C$8+Ipoteze!$C$136 -> 56858.684 | I41: =IF(B41>=4,INDEX('Break-even'!$C$8:$F$8,1,4),INDEX('Break-even'!$C$8:$F$8,1,B41)+(INDEX('Break-even'!$C$8:$F$8,1,B41+1)-INDEX('Break-even'!$C$8:$F$8,1,B41))*LN(A41/INDEX('Break-even'!$C$6:$F$6,1,B41))/LN(INDEX('Break-even'!$C$6:$F$6,1,B41+1)/INDEX('Break-even'!$C$6:$F$6,1,B41))) -> 10.248488 | J41: =H41+A41*I41 -> 59420.806 | K41: =J41/A41 -> 237.68322 | L41: =D41-J41 -> -45496.498 | M41: =IF(J41<D41,1,0) -> 0
A42: 500 | B42: =MATCH(A42,'Break-even'!$C$6:$F$6,1) -> 1 | C42: =IF(B42>=4,INDEX('Break-even'!$C$7:$F$7,1,4),INDEX('Break-even'!$C$7:$F$7,1,B42)+(INDEX('Break-even'!$C$7:$F$7,1,B42+1)-INDEX('Break-even'!$C$7:$F$7,1,B42))*LN(A42/INDEX('Break-even'!$C$6:$F$6,1,B42))/LN(INDEX('Break-even'!$C$6:$F$6,1,B42+1)/INDEX('Break-even'!$C$6:$F$6,1,B42))) -> 43.770029 | D42: =A42*C42 -> 21885.014 | E42: =CEILING(A42/('Break-even'!$C$23*Ipoteze!$C$20),1) -> 1 | F42: =MIN(Ipoteze!$C$20,CEILING(A42/('Break-even'!$C$23*E42),1)) -> 1 | G42: =F42*CEILING(E42/Ipoteze!$C$137,1) -> 1 | H42: =(E42*('Break-even'!$C$17+Ipoteze!$C$118)+'Break-even'!$C$18)/Ipoteze!$C$90+'Break-even'!$C$20+(G42-1)*'Break-even'!$C$21+G42*'Break-even'!$C$19+(E42*Ipoteze!$C$134+Ipoteze!$C$135)*'Break-even'!$C$22+Ipoteze!$C$124*E42*'Break-even'!$C$17+Ipoteze!$C$123*Ipoteze!$C$8+Ipoteze!$C$136 -> 56858.684 | I42: =IF(B42>=4,INDEX('Break-even'!$C$8:$F$8,1,4),INDEX('Break-even'!$C$8:$F$8,1,B42)+(INDEX('Break-even'!$C$8:$F$8,1,B42+1)-INDEX('Break-even'!$C$8:$F$8,1,B42))*LN(A42/INDEX('Break-even'!$C$6:$F$6,1,B42))/LN(INDEX('Break-even'!$C$6:$F$6,1,B42+1)/INDEX('Break-even'!$C$6:$F$6,1,B42))) -> 10.052818 | J42: =H42+A42*I42 -> 61885.093 | K42: =J42/A42 -> 123.77019 | L42: =D42-J42 -> -40000.079 | M42: =IF(J42<D42,1,0) -> 0
A43: 1000 | B43: =MATCH(A43,'Break-even'!$C$6:$F$6,1) -> 2 | C43: =IF(B43>=4,INDEX('Break-even'!$C$7:$F$7,1,4),INDEX('Break-even'!$C$7:$F$7,1,B43)+(INDEX('Break-even'!$C$7:$F$7,1,B43+1)-INDEX('Break-even'!$C$7:$F$7,1,B43))*LN(A43/INDEX('Break-even'!$C$6:$F$6,1,B43))/LN(INDEX('Break-even'!$C$6:$F$6,1,B43+1)/INDEX('Break-even'!$C$6:$F$6,1,B43))) -> 31.842824 | D43: =A43*C43 -> 31842.824 | E43: =CEILING(A43/('Break-even'!$C$23*Ipoteze!$C$20),1) -> 1 | F43: =MIN(Ipoteze!$C$20,CEILING(A43/('Break-even'!$C$23*E43),1)) -> 1 | G43: =F43*CEILING(E43/Ipoteze!$C$137,1) -> 1 | H43: =(E43*('Break-even'!$C$17+Ipoteze!$C$118)+'Break-even'!$C$18)/Ipoteze!$C$90+'Break-even'!$C$20+(G43-1)*'Break-even'!$C$21+G43*'Break-even'!$C$19+(E43*Ipoteze!$C$134+Ipoteze!$C$135)*'Break-even'!$C$22+Ipoteze!$C$124*E43*'Break-even'!$C$17+Ipoteze!$C$123*Ipoteze!$C$8+Ipoteze!$C$136 -> 56858.684 | I43: =IF(B43>=4,INDEX('Break-even'!$C$8:$F$8,1,4),INDEX('Break-even'!$C$8:$F$8,1,B43)+(INDEX('Break-even'!$C$8:$F$8,1,B43+1)-INDEX('Break-even'!$C$8:$F$8,1,B43))*LN(A43/INDEX('Break-even'!$C$6:$F$6,1,B43))/LN(INDEX('Break-even'!$C$6:$F$6,1,B43+1)/INDEX('Break-even'!$C$6:$F$6,1,B43))) -> 9.8571488 | J43: =H43+A43*I43 -> 66715.833 | K43: =J43/A43 -> 66.715833 | L43: =D43-J43 -> -34873.009 | M43: =IF(J43<D43,1,0) -> 0
A44: 1500 | B44: =MATCH(A44,'Break-even'!$C$6:$F$6,1) -> 2 | C44: =IF(B44>=4,INDEX('Break-even'!$C$7:$F$7,1,4),INDEX('Break-even'!$C$7:$F$7,1,B44)+(INDEX('Break-even'!$C$7:$F$7,1,B44+1)-INDEX('Break-even'!$C$7:$F$7,1,B44))*LN(A44/INDEX('Break-even'!$C$6:$F$6,1,B44))/LN(INDEX('Break-even'!$C$6:$F$6,1,B44+1)/INDEX('Break-even'!$C$6:$F$6,1,B44))) -> 29.735152 | D44: =A44*C44 -> 44602.728 | E44: =CEILING(A44/('Break-even'!$C$23*Ipoteze!$C$20),1) -> 1 | F44: =MIN(Ipoteze!$C$20,CEILING(A44/('Break-even'!$C$23*E44),1)) -> 1 | G44: =F44*CEILING(E44/Ipoteze!$C$137,1) -> 1 | H44: =(E44*('Break-even'!$C$17+Ipoteze!$C$118)+'Break-even'!$C$18)/Ipoteze!$C$90+'Break-even'!$C$20+(G44-1)*'Break-even'!$C$21+G44*'Break-even'!$C$19+(E44*Ipoteze!$C$134+Ipoteze!$C$135)*'Break-even'!$C$22+Ipoteze!$C$124*E44*'Break-even'!$C$17+Ipoteze!$C$123*Ipoteze!$C$8+Ipoteze!$C$136 -> 56858.684 | I44: =IF(B44>=4,INDEX('Break-even'!$C$8:$F$8,1,4),INDEX('Break-even'!$C$8:$F$8,1,B44)+(INDEX('Break-even'!$C$8:$F$8,1,B44+1)-INDEX('Break-even'!$C$8:$F$8,1,B44))*LN(A44/INDEX('Break-even'!$C$6:$F$6,1,B44))/LN(INDEX('Break-even'!$C$6:$F$6,1,B44+1)/INDEX('Break-even'!$C$6:$F$6,1,B44))) -> 9.5185553 | J44: =H44+A44*I44 -> 71136.517 | K44: =J44/A44 -> 47.424345 | L44: =D44-J44 -> -26533.789 | M44: =IF(J44<D44,1,0) -> 0
A45: 2000 | B45: =MATCH(A45,'Break-even'!$C$6:$F$6,1) -> 2 | C45: =IF(B45>=4,INDEX('Break-even'!$C$7:$F$7,1,4),INDEX('Break-even'!$C$7:$F$7,1,B45)+(INDEX('Break-even'!$C$7:$F$7,1,B45+1)-INDEX('Break-even'!$C$7:$F$7,1,B45))*LN(A45/INDEX('Break-even'!$C$6:$F$6,1,B45))/LN(INDEX('Break-even'!$C$6:$F$6,1,B45+1)/INDEX('Break-even'!$C$6:$F$6,1,B45))) -> 28.239735 | D45: =A45*C45 -> 56479.47 | E45: =CEILING(A45/('Break-even'!$C$23*Ipoteze!$C$20),1) -> 1 | F45: =MIN(Ipoteze!$C$20,CEILING(A45/('Break-even'!$C$23*E45),1)) -> 1 | G45: =F45*CEILING(E45/Ipoteze!$C$137,1) -> 1 | H45: =(E45*('Break-even'!$C$17+Ipoteze!$C$118)+'Break-even'!$C$18)/Ipoteze!$C$90+'Break-even'!$C$20+(G45-1)*'Break-even'!$C$21+G45*'Break-even'!$C$19+(E45*Ipoteze!$C$134+Ipoteze!$C$135)*'Break-even'!$C$22+Ipoteze!$C$124*E45*'Break-even'!$C$17+Ipoteze!$C$123*Ipoteze!$C$8+Ipoteze!$C$136 -> 56858.684 | I45: =IF(B45>=4,INDEX('Break-even'!$C$8:$F$8,1,4),INDEX('Break-even'!$C$8:$F$8,1,B45)+(INDEX('Break-even'!$C$8:$F$8,1,B45+1)-INDEX('Break-even'!$C$8:$F$8,1,B45))*LN(A45/INDEX('Break-even'!$C$6:$F$6,1,B45))/LN(INDEX('Break-even'!$C$6:$F$6,1,B45+1)/INDEX('Break-even'!$C$6:$F$6,1,B45))) -> 9.2783195 | J45: =H45+A45*I45 -> 75415.323 | K45: =J45/A45 -> 37.707662 | L45: =D45-J45 -> -18935.853 | M45: =IF(J45<D45,1,0) -> 0
...

Sheet Capacitate
A1: CAPACITATE: unități pe schimb per stație, necesar de stații și gâtuirea liniei
A2: Unități/schimb = minute productive pe schimb × posturi paralele / timp ciclu. Necesar = volum / (capacitate anuală pe 1 schimb × utilizare țintă), rotunjit în sus. Pentru CNC și SMT necesarul vine din Scenarii (cu 2 schimburi înainte de a cumpăra încă o mașină).
A4: Stație | B4: Timp ciclu (min) | C4: Posturi paralele | D4: Unități / schimb | E4: Unități / an (1 schimb) | F4: Necesar @100 | G4: Necesar @1.000 | H4: Necesar @5.000 | I4: Necesar @20.000 | J4: Utilizare @20.000 | L4: Notă
A5: Banc asamblare (1 operator) | B5: =Ipoteze!D$66 -> 25 | C5: 1 | D5: =Ipoteze!$C$18*C5/B5 -> 16.32 | E5: =D5*Ipoteze!$C$15 -> 3590.4 | F5: =Scenarii!C34 -> 0.05013369 | G5: =Scenarii!D34 -> 0.2785205 | H5: =Scenarii!E34 -> 1.114082 | I5: =Scenarii!F34 -> 3.342246 | J5: =I5/MAX(1,CEILING(I5,1)) -> 0.8355615 | L5: Ciclul = manopera totală la 1.000 buc./an; necesarul folosește minutele per volum (Ipoteze 4). Gâtuirea reală a T0 = oamenii.
A6: Stație flash | B6: =Ipoteze!$C$68 -> 2 | C6: =Ipoteze!$C$69 -> 4 | D6: =Ipoteze!$C$18*C6/B6 -> 816 | E6: =D6*Ipoteze!$C$15 -> 179520 | F6: =MAX(1,CEILING(Ipoteze!C$9/(E6*Ipoteze!$C$21),1)) -> 1 | G6: =MAX(1,CEILING(Ipoteze!D$9/(E6*Ipoteze!$C$21),1)) -> 1 | H6: =MAX(1,CEILING(Ipoteze!E$9/(E6*Ipoteze!$C$21),1)) -> 1 | I6: =MAX(1,CEILING(Ipoteze!F$9/(E6*Ipoteze!$C$21),1)) -> 1 | J6: =Ipoteze!F$9/(E6*IF(I6<1,1,CEILING(I6,1))) -> 0.1114082 | L6: Espressif Flash Download Tool, mod Factory
A7: Jig test funcțional | B7: =Ipoteze!$C$67 -> 4 | C7: 1 | D7: =Ipoteze!$C$18*C7/B7 -> 102 | E7: =D7*Ipoteze!$C$15 -> 22440 | F7: =MAX(1,CEILING(Ipoteze!C$9/(E7*Ipoteze!$C$21),1)) -> 1 | G7: =MAX(1,CEILING(Ipoteze!D$9/(E7*Ipoteze!$C$21),1)) -> 1 | H7: =MAX(1,CEILING(Ipoteze!E$9/(E7*Ipoteze!$C$21),1)) -> 1 | I7: =MAX(1,CEILING(Ipoteze!F$9/(E7*Ipoteze!$C$21),1)) -> 2 | J7: =Ipoteze!F$9/(E7*IF(I7<1,1,CEILING(I7,1))) -> 0.4456328 | L7: Fixturfab; cutie ecranată pentru RSSI
A8: Raft rodaj (burn-in) | B8: =Ipoteze!$C$70 -> 10 | C8: =Ipoteze!$C$71 -> 20 | D8: =Ipoteze!$C$18*C8/B8 -> 816 | E8: =D8*Ipoteze!$C$15 -> 179520 | F8: =MAX(1,CEILING(Ipoteze!C$9/(E8*Ipoteze!$C$21),1)) -> 1 | G8: =MAX(1,CEILING(Ipoteze!D$9/(E8*Ipoteze!$C$21),1)) -> 1 | H8: =MAX(1,CEILING(Ipoteze!E$9/(E8*Ipoteze!$C$21),1)) -> 1 | I8: =MAX(1,CEILING(Ipoteze!F$9/(E8*Ipoteze!$C$21),1)) -> 1 | J8: =Ipoteze!F$9/(E8*IF(I8<1,1,CEILING(I8,1))) -> 0.1114082 | L8: Nesupravegheat
A9: Laser MOPA marcare | B9: =Ipoteze!$C$72 -> 1 | C9: 1 | D9: =Ipoteze!$C$18*C9/B9 -> 408 | E9: =D9*Ipoteze!$C$15 -> 89760 | F9: =MAX(1,CEILING(Ipoteze!C$9/(E9*Ipoteze!$C$21),1)) -> 1 | G9: =MAX(1,CEILING(Ipoteze!D$9/(E9*Ipoteze!$C$21),1)) -> 1 | H9: =MAX(1,CEILING(Ipoteze!E$9/(E9*Ipoteze!$C$21),1)) -> 1 | I9: =MAX(1,CEILING(Ipoteze!F$9/(E9*Ipoteze!$C$21),1)) -> 1 | J9: =Ipoteze!F$9/(E9*IF(I9<1,1,CEILING(I9,1))) -> 0.2228164 | L9: Serie + CE/WEEE după anodizare
A10: CNC mărimea S (1 mașină) | B10: =Ipoteze!$C$125 -> 24 | C10: 1 | D10: =Ipoteze!$C$18*C10/B10 -> 17 | E10: =D10*Ipoteze!$C$15 -> 3740 | F10: =Scenarii!C42 -> 1 | G10: =Scenarii!D42 -> 1 | H10: =Scenarii!E42 -> 1 | I10: =Scenarii!F42 -> 3 | J10: =Scenarii!F45 -> 0.8912656 | L10: Necesar = mașini (cu până la 2 schimburi). Gâtuirea scenariilor C/D.
A11: CNC mărimea M, comparație (1 mașină) | B11: =Ipoteze!$C$126 -> 45 | C11: 1 | D11: =Ipoteze!$C$18*C11/B11 -> 9.0666667 | E11: =D11*Ipoteze!$C$15 -> 1994.6667 | F11: =CEILING(Ipoteze!C$9/(E11*Ipoteze!$C$20),1) -> 1 | G11: =CEILING(Ipoteze!D$9/(E11*Ipoteze!$C$20),1) -> 1 | H11: =CEILING(Ipoteze!E$9/(E11*Ipoteze!$C$20),1) -> 2 | I11: =CEILING(Ipoteze!F$9/(E11*Ipoteze!$C$20),1) -> 6 | J11: =Ipoteze!F$9/(E11*I11*Ipoteze!$C$20) -> 0.8355615 | L11: Comparație M: ciclu de ~1,9× mai lung → ~0,53× seturi pe mașină
A12: Linie SMT (NeoDen4 + reflow + AOI) | B12: =Ipoteze!$C$52/Ipoteze!$C$149*60+Ipoteze!$C$150 -> 4.1 | C12: 1 | D12: =Ipoteze!$C$18*C12/B12 -> 99.512195 | E12: =D12*Ipoteze!$C$15 -> 21892.683 | F12: =Scenarii!C50 -> 1 | G12: =Scenarii!D50 -> 1 | H12: =Scenarii!E50 -> 1 | I12: =Scenarii!F50 -> 1 | J12: =Ipoteze!F$9/(E12*Scenarii!F50*Scenarii!F51) -> 0.91354724 | L12: Reflow-ul NeoDen IN6 nu e gâtuire la aceste volume
A14: Gâtuirea T0 (stația cu cele mai puține unități/schimb) | D14: =MIN(D5:D9) -> 16.32 | E14: =INDEX(A5:A9,MATCH(D14,D5:D9,0)) -> Banc asamblare (1 operator)
A15: Gâtuirea scenariilor C/D (unități/schimb) | D15: =MIN(D5:D10) -> 16.32 | E15: =INDEX(A5:A10,MATCH(D15,D5:D10,0)) -> Banc asamblare (1 operator)
A17: Personal necesar (persoane) | F17: =Ipoteze!C$9 -> 100 | G17: =Ipoteze!D$9 -> 1000 | H17: =Ipoteze!E$9 -> 5000 | I17: =Ipoteze!F$9 -> 20000
A18: Scenariul B (operatori + QC + gestionar) | F18: =Scenarii!C38 -> 1 | G18: =Scenarii!D38 -> 1 | H18: =Scenarii!E38 -> 3 | I18: =Scenarii!F38 -> 6
A19: Scenariul C (+ CNC) | F19: =Scenarii!C55 -> 2 | G19: =Scenarii!D55 -> 2 | H19: =Scenarii!E55 -> 5 | I19: =Scenarii!F55 -> 10
A20: Scenariul D (+ SMT) | F20: =Scenarii!C56 -> 3 | G20: =Scenarii!D56 -> 3 | H20: =Scenarii!E56 -> 6 | I20: =Scenarii!F56 -> 11
